OrderbookTest/TestFiles/All_Order_Types_Large.txt
A B GoodForDay 105 67 1
A B FillOrKill 104 34 2
C 1
M 1 B 104 61
C 2
M 1 B 101 90
A B Market 98 78 3
M 1 S 103 17
M 2 B 103 94
C 1
C 1
M 3 B 98 66
M 2 B 97 92
A B Market 99 74 4
M 4 S 102 39
A B GoodForDay 96 18 5
C 4
A S Market 101 66 6
C 6
M 3 B 102 55
M 5 S 105 49
M 1 S 97 73
C 6
M 6 B 102 98
C 2
C 6
A S GoodForDay 103 61 7
A S FillAndKill 99 42 8
A S FillOrKill 100 77 9
M 9 B 104 83
C 2
A S FillAndKill 98 72 10
A B Market 98 35 11
C 1
A B GoodTillCancel 101 76 12
A S Market 100 62 13
C 8
A S FillOrKill 105 76 14
C 5
C 8
C 13
C 4
A S GoodForDay 97 62 15
A B Market 98 65 16
M 12 B 96 68
M 2 B 100 95
C 13
C 5
M 8 B 96 63
M 15 S 100 58
M 10 S 100 37
M 5 S 97 79
M 3 S 99 80
A S GoodForDay 101 84 17
M 8 S 100 46
C 2
A S GoodTillCancel 103 22 18
C 3
M 12 B 101 72
M 7 S 104 52
A B GoodTillCancel 101 21 19
M 19 B 99 38
M 18 S 105 19
C 16
A S Market 102 19 20
M 3 B 103 18
A S GoodForDay 101 72 21
A B Market 105 71 22
C 9
A S FillOrKill 99 25 23
C 9
C 5
A S GoodTillCancel 98 71 24
C 16
M 21 B 105 33
C 13
C 22
C 7
M 11 B 102 12
C 7
A S FillAndKill 101 72 25
M 4 S 103 74
M 19 B 98 77
C 8
M 9 S 104 96
C 20
A B FillOrKill 101 16 26
A B Market 104 22 27
M 3 B 99 96
C 3
M 3 S 95 13
C 4
C 3
M 4 S 97 90
A S GoodTillCancel 104 79 28
C 11
C 13
M 16 S 100 67
C 26
C 26
A B Market 97 66 29
M 20 B 96 69
A S GoodForDay 101 62 30
M 29 S 105 84
M 15 B 97 18
A S FillOrKill 95 45 31
A S Market 100 83 32
C 12
A S Market 103 96 33
M 15 S 96 88
A B Market 103 66 34
M 14 S 97 87
M 14 S 103 71
M 24 B 100 37
M 33 B 105 46
C 7
C 22
A B FillAndKill 95 52 35
A B GoodForDay 96 59 36
M 7 S 100 43
C 34
M 34 S 96 75
A B FillOrKill 105 67 37
A S GoodTillCancel 101 23 38
A B FillAndKill 102 22 39
M 38 B 104 99
M 3 B 104 100
M 37 S 99 34
C 24
M 29 B 101 30
M 18 B 102 87
C 20
M 13 S 105 61
M 22 B 102 56
M 19 S 101 83
C 20
C 9
M 34 S 98 70
A B GoodForDay 96 85 40
C 35
M 32 B 104 36
C 36
A S Market 97 76 41
C 17
M 41 B 97 88
C 3
A S GoodTillCancel 100 55 42
C 29
A S Market 103 69 43
A B FillOrKill 101 12 44
A B GoodForDay 104 84 45
M 22 B 103 86
M 20 S 105 99
C 26
M 17 B 100 37
C 45
C 18
C 18
M 30 S 100 12
M 10 B 99 73
C 41
M 13 S 105 37
A B Market 100 45 46
M 23 S 98 73
A S FillOrKill 95 98 47
M 30 B 99 62
C 10
A B FillAndKill 102 100 48
A B FillOrKill 100 10 49
C 29
C 24
A B Market 97 23 50
A B FillAndKill 104 34 51
C 20
M 22 B 95 33
C 9
A S FillAndKill 101 33 52
M 5 S 101 90
M 33 B 98 37
A S FillOrKill 103 67 53
C 32
A S FillAndKill 96 58 54
C 7
A B FillAndKill 103 89 55
M 2 B 101 94
A B FillOrKill 100 23 56
A S FillOrKill 96 70 57
C 49
M 13 S 101 50
A B FillOrKill 100 52 58
C 7
C 21
M 2 S 97 20
C 53
C 45
C 18
M 32 S 99 79
C 55
M 37 S 105 87
M 57 S 99 36
C 18
M 22 S 96 54
A B GoodTillCancel 104 21 59
M 58 B 104 15
M 29 B 99 42
A B FillOrKill 102 12 60
C 31
C 16
M 10 S 98 72
C 57
M 7 B 102 92
M 28 B 96 37
M 51 S 98 55
A S GoodForDay 105 68 61
C 50
C 39
C 36
A S FillAndKill 102 48 62
A B FillOrKill 105 59 63
M 42 S 99 27
C 2
M 44 S 99 78
A B FillOrKill 99 74 64
M 27 B 102 72
A S FillAndKill 99 30 65
C 54
C 34
M 7 B 99 26
C 18
M 25 B 96 89
C 34
M 27 S 100 27
M 54 B 102 64
C 18
C 29
M 40 S 99 70
M 13 B 103 38
A B GoodForDay 95 61 66
M 8 S 100 23
C 46
M 41 B 102 24
C 12
A B FillAndKill 104 77 67
A B Market 103 34 68
C 55
M 48 B 105 91
C 57
C 16
M 13 S 97 41
C 39
M 9 B 99 45
A S FillOrKill 95 68 69
A B FillAndKill 99 99 70
A B GoodForDay 101 30 71
M 23 B 96 17
A B FillOrKill 101 22 72
M 64 B 100 88
A B GoodForDay 101 17 73
M 70 B 96 65
A B Market 98 15 74
A B FillAndKill 104 80 75
M 60 B 104 28
M 52 S 97 52
M 40 B 96 67
A S GoodForDay 96 14 76
M 35 B 105 26
M 63 B 102 18
C 39
A S FillOrKill 97 73 77
C 18
C 9
M 71 B 97 42
M 17 S 98 77
M 16 B 98 95
M 76 S 105 38
C 34
M 25 B 97 63
M 64 S 97 50
C 44
M 57 S 103 39
C 52
A S GoodTillCancel 99 18 78
M 20 S 99 96
M 27 B 103 33
M 24 B 99 17
A B FillOrKill 96 66 79
C 33
M 18 B 100 28
C 51
C 11
A B FillOrKill 96 57 80
A B GoodTillCancel 99 36 81
C 40
A S GoodForDay 100 24 82
A S GoodForDay 100 15 83
C 11
C 61
A S GoodForDay 105 25 84
C 30
M 3 B 100 68
C 64
C 9
M 13 S 97 70
C 63
M 56 B 104 18
C 84
A S GoodForDay 104 64 85
C 42
C 53
M 20 S 105 62
A S FillOrKill 103 30 86
A B FillAndKill 97 66 87
A B GoodTillCancel 97 37 88
M 50 B 99 15
A B FillAndKill 99 96 89
M 15 B 104 88
M 38 B 100 19
M 37 S 100 52
A B FillAndKill 100 72 90
M 11 B 98 78
C 73
A S GoodForDay 105 96 91
C 64
C 79
A B GoodForDay 99 54 92
A B FillAndKill 102 10 93
C 62
M 29 B 103 61
A S GoodForDay 103 63 94
C 7
A S GoodTillCancel 102 18 95
C 2
M 7 S 100 62
M 79 B 99 33
A S Market 105 90 96
C 39
A B FillAndKill 104 73 97
C 43
M 15 B 103 46
M 45 S 104 67
A S Market 101 15 98
M 98 S 102 37
A S Market 96 39 99
M 62 B 99 54
M 68 S 100 45
A B GoodForDay 104 72 100
C 24
C 73
C 87
C 66
C 82
C 75
A S GoodForDay 96 48 101
A B GoodTillCancel 96 49 102
A S FillOrKill 99 85 103
M 14 S 98 75
C 91
C 33
M 84 B 98 67
M 56 B 95 88
C 82
C 77
M 17 B 99 96
C 99
M 18 S 102 27
M 70 B 101 83
C 92
C 58
M 102 S 102 27
A B FillOrKill 103 38 104
M 40 B 97 10
A B FillOrKill 95 23 105
A S GoodTillCancel 104 62 106
C 6
C 34
C 83
C 91
M 99 S 98 31
C 34
M 56 S 99 54
M 10 S 99 17
C 83
C 31
A B FillOrKill 104 67 107
M 86 S 104 34
C 99
A B FillOrKill 99 21 108
A S GoodForDay 104 92 109
M 10 B 105 12
A S GoodTillCancel 103 17 110
A B Market 103 49 111
C 22
A S Market 99 22 112
C 11
M 68 S 101 48
C 8
A S GoodForDay 99 34 113
M 19 S 105 50
A S FillAndKill 97 92 114
C 24
M 8 B 97 15
M 107 S 96 20
M 49 B 103 75
C 74
C 105
A S Market 98 33 115
C 69
M 85 S 100 33
C 48
C 7
C 108
M 45 S 103 37
A B GoodForDay 105 65 116
A S GoodForDay 99 13 117
C 36
C 77
C 105
C 19
A S GoodForDay 95 56 118
M 29 S 100 100
A B FillAndKill 102 76 119
A S FillAndKill 102 45 120
A B FillAndKill 104 63 121
A B FillOrKill 103 53 122
A S Market 99 64 123
M 30 B 97 47
A S FillAndKill 98 21 124
A B GoodForDay 104 91 125
M 2 B 97 49
M 98 S 95 87
M 89 S 102 55
M 13 B 98 52
M 119 S 102 32
M 116 S 99 50
C 33
A S GoodTillCancel 95 92 126
A B Market 104 98 127
A S GoodTillCancel 104 31 128
C 52
C 98
A S FillAndKill 98 79 129
M 60 S 103 79
M 3 B 98 93
C 88
A B Market 95 43 130
A S FillOrKill 100 33 131
M 69 S 100 27
A B GoodForDay 100 58 132
C 23
A S GoodTillCancel 101 79 133
M 131 S 105 84
M 86 S 96 25
M 65 S 100 73
C 15
A S Market 100 49 134
C 45
C 66
M 65 B 105 61
A S GoodForDay 104 16 135
C 32
M 3 S 102 56
A B Market 102 22 136
A B Market 96 55 137
C 99
C 112
C 131
M 12 S 98 96
M 79 B 100 10
C 22
C 136
A B FillAndKill 101 27 138
A B GoodTillCancel 97 74 139
C 85
A S FillAndKill 105 27 140
M 96 B 97 66
M 118 S 99 73
C 83
A B GoodForDay 95 60 141
M 107 B 105 22
M 37 B 99 42
C 28
A B Market 98 17 142
A B FillAndKill 105 98 143
C 132
M 86 B 100 18
A S GoodTillCancel 103 93 144
M 135 S 101 46
C 97
M 49 B 95 95
M 40 B 98 42
C 29
M 56 B 102 50
M 23 B 97 42
A B FillAndKill 104 95 145
A S FillOrKill 103 58 146
C 115
A S FillAndKill 104 88 147
A B GoodForDay 102 25 148
A B FillOrKill 105 91 149
A S GoodTillCancel 105 91 150
C 55
C 64
C 111
M 15 B 96 13
C 73
C 67
A B GoodForDay 99 66 151
M 127 B 102 95
A S FillOrKill 105 22 152
M 11 B 98 46
C 77
A S GoodTillCancel 96 52 153
A S Market 102 52 154
C 52
A B FillOrKill 104 13 155
C 55
C 147
M 74 B 96 13
M 154 S 100 76
A S GoodForDay 102 80 156
C 57
A S GoodForDay 102 18 157
A S GoodForDay 102 47 158
M 8 B 96 82
C 24
M 86 B 100 63
C 42
M 97 B 98 38
C 122
M 31 S 98 38
C 80
A S Market 95 26 159
C 52
C 123
C 149
A S GoodForDay 100 61 160
M 6 S 97 72
A S FillAndKill 103 92 161
C 14
M 135 S 95 96
C 128
C 6
C 30
M 41 B 100 99
A B FillAndKill 104 33 162
C 47
A S Market 98 28 163
C 112
C 140
M 4 B 95 35
C 69
M 147 B 105 64
C 107
A S Market 100 25 164
M 19 S 105 65
M 64 S 104 96
C 148
M 145 B 102 42
M 103 B 104 48
A B FillOrKill 104 53 165
C 142
C 148
C 19
C 145
C 152
M 47 B 104 76
A B FillOrKill 96 66 166
C 101
M 50 S 105 13
M 62 S 97 40
A B FillAndKill 104 66 167
M 119 S 95 97
A B Market 97 34 168
M 24 S 103 98
A S FillOrKill 95 33 169
C 82
A B GoodTillCancel 100 96 170
M 131 B 102 28
A B FillOrKill 100 22 171
C 101
A S FillOrKill 96 84 172
C 2
